void bad() {
  try {
    /* ... */
  }
  catch(std::exception a_copy_of_the_thrown_exception) {
    // Do something with a_copy_of_the_thrown_exception
  }
}
